Workbook

Sheet Cover
A1: M M Forgings - Equity valuation: DCF, reverse DCF and the credit-vs-equity gap
A2: Prepared by Gaurav Waghmode | Price date 29-Sep-2026 | Student valuation exercise - not investment advice; author is not SEBI-registered
A4: CMP (Rs) | B4: =DCF!B4 -> 612
A5: DCF value per share - active scenario (Rs) | B5: =DCF!B49 -> 118.07256
A6: Upside / (downside) | B6: =DCF!B50 -> -0.80707098
A7: WACC | B7: =DCF!B20 -> 0.12954168
A8: Terminal growth / RONIC | B8: =TEXT(DCF!B21,"0.0%")&" / "&TEXT(DCF!B22,"0%") -> 6.0% / 15%
A9: Market EV / TTM EBITDA | B9: =DCF!B56 -> 14.297397
A10: Exit EV/EBITDA the price implies (FY31E) | B10: =DCF!B61 -> 12.143214
A11: Steady-state EBITDA margin the price implies | B11: =DCF!B64 -> 0.41000355
A12: FY26 post-tax ROIC | B12: =Model!F49 -> 0.061964491
A13: FY26 interest coverage (EBITDA / interest) | B13: =Model!F53 -> 3.5897436
A14: FY26 net debt / EBITDA | B14: =Model!F52 -> 4.3785714
A15: Scenario running | B15: =CHOOSE(Model!B3,"Bear","Base","Bull") -> Base
A17: THE QUESTION THIS MODEL ANSWERS
A18: CARE rates MMFL A (Stable): lenders are comfortable. Equity investors pay ~14x EV/EBITDA and ~3x book for a business earning ROIC below its cost of capital.
A19: Is that a mistake, or is the market pricing a recovery? The reverse-DCF block on the DCF sheet shows exactly what has to go right.
A21: HOW TO USE
A22: 1. Yellow cells on Model (growth, margin, capex, NWC) and DCF (beta, cost of debt, g, RONIC) drive everything.
A23: 2. Flip Model!B3 (1 Bear / 2 Base / 3 Bull). Sensitivity tables on the DCF sheet are live formulas.
A24: 3. Reverse_DCF_Grid maps value across revenue CAGR x EBITDA margin (live). mmfl_dcf.py is an independent Python replica that re-computes everything and checks Excel.
A25: 4. After each quarterly result, add the quarter on Quarterly and re-check the FY27E revenue run-rate.
A27: COLOUR CODE: blue = hard-coded input | black = formula | green = link to another sheet | yellow fill = key assumption
A29: SOURCES
A30: Screener.in consolidated financials, ratios, quarterly results and shareholding (fetched 29-Sep-2026).
A31: CARE Ratings press releases (Apr and Jun 2026) for the A (Stable) rating and PBILDT definition.
... A33: VERIFY every blue number against the FY26 annual report (cash balance, tax note, capitalised interest) before an interview.

Sheet Model
A1: M M Forgings Ltd (NSE: MMFL) - Operating model (consolidated)
A2: History: Screener.in (consolidated), fetched 29-Sep-2026. FY27E-FY31E = analyst estimates. Blue = input, black = formula, green = link, yellow = key assumption.
A3: Scenario switch (1 Bear, 2 Base, 3 Bull) | B3: 2
B4: Bear | C4: Base | D4: Bull | E4: Active
A5: Revenue growth delta (added every year) | B5: -0.05 | C5: 0 | D5: 0.03 | E5: =CHOOSE($B$3,B5,C5,D5) -> 0 | G5: Dividend payout (forecast) | I5: 0.1
A6: EBITDA margin delta | B6: -0.02 | C6: 0 | D6: 0.02 | E6: =CHOOSE($B$3,B6,C6,D6) -> 0
A7: NWC % of revenue delta | B7: 0.04 | C7: 0 | D7: -0.03 | E7: =CHOOSE($B$3,B7,C7,D7) -> 0
A9: INR crore unless stated | B9: FY22 | C9: FY23 | D9: FY24 | E9: FY25 | F9: FY26 | G9: FY27E | H9: FY28E | I9: FY29E | J9: FY30E | K9: FY31E | L9: Source / comment
A10: INCOME STATEMENT
A11: Revenue from operations | B11: 1140 | C11: 1462 | D11: 1563 | E11: 1525 | F11: 1590 | G11: =F11*(1+G12+$E$5) -> 1828.5 | H11: =G11*(1+H12+$E$5) -> 2084.49 | I11: =H11*(1+I12+$E$5) -> 2334.6288 | J11: =I11*(1+J12+$E$5) -> 2568.0917 | K11: =J11*(1+K12+$E$5) -> 2799.2199 | L11: Screener consolidated P&L. TTM (to Jun-26) Rs1,649cr; Q1FY27 Rs420cr (+16% YoY).
A12: Revenue growth (base input; scenario delta added) | C12: =C11/B11-1 -> 0.28245614 | D12: =D11/C11-1 -> 0.069083447 | E12: =E11/D11-1 -> -0.02431222 | F12: =F11/E11-1 -> 0.042622951 | G12: 0.15 | H12: 0.14 | I12: 0.12 | J12: 0.1 | K12: 0.09 | L12: Capacity from FY25-26 capex (CWIP Rs335cr at FY26) ramps up; Q1FY27 +16% YoY.
A13: EBITDA (= PBILDT in rating-agency terms) | B13: 209 | C13: 273 | D13: 293 | E13: 296 | F13: 280 | G13: =G11*G15 -> 338.2725 | H13: =H11*H15 -> 396.0531 | I13: =I11*I15 -> 455.25262 | J13: =J11*J15 -> 500.77788 | K13: =K11*K15 -> 545.84789
A14: EBITDA margin - base input | G14: 0.185 | H14: 0.19 | I14: 0.195 | J14: 0.195 | K14: 0.195 | L14: FY22-FY26 range 17.6%-19.4%; Q1FY27 17.9%. Base assumes some operating leverage as new capacity fills.
A15: EBITDA margin | B15: =B13/B11 -> 0.18333333 | C15: =C13/C11 -> 0.18673051 | D15: =D13/D11 -> 0.18746001 | E15: =E13/E11 -> 0.19409836 | F15: =F13/F11 -> 0.17610063 | G15: =G14+$E$6 -> 0.185 | H15: =H14+$E$6 -> 0.19 | I15: =I14+$E$6 -> 0.195 | J15: =J14+$E$6 -> 0.195 | K15: =K14+$E$6 -> 0.195
A16: Depreciation & amortisation | B16: 68 | C16: 79 | D16: 83 | E16: 93 | F16: 103 | G16: =G11*G17 -> 124.338 | H16: =H11*H17 -> 139.66083 | I16: =I11*I17 -> 154.0855 | J16: =J11*J17 -> 166.92596 | K16: =K11*K17 -> 179.15008
A17: D&A % of revenue | B17: =B16/B11 -> 0.059649123 | C17: =C16/C11 -> 0.054035568 | D17: =D16/D11 -> 0.053103007 | E17: =E16/E11 -> 0.060983607 | F17: =F16/F11 -> 0.064779874 | G17: 0.068 | H17: 0.067 | I17: 0.066 | J17: 0.065 | K17: 0.064 | L17: Steps up in FY27 as the Rs335cr CWIP is capitalised.
A18: EBIT | B18: =B13-B16 -> 141 | C18: =C13-C16 -> 194 | D18: =D13-D16 -> 210 | E18: =E13-E16 -> 203 | F18: =F13-F16 -> 177 | G18: =G13-G16 -> 213.9345 | H18: =H13-H16 -> 256.39227 | I18: =I13-I16 -> 301.16712 | ... K18: =K13-K16 -> 366.69781
A19: Other income | B19: 16 | C19: 12 | D19: 22 | E19: 23 | F19: 16 | G19: 75 | H19: 18 | I19: 18 | J19: 18 | K19: 18 | L19: FY27E includes Rs63cr one-off booked in Q1FY27 (non-operating: excluded from FCFF).
A20: Finance costs | B20: 28 | C20: 30 | D20: 42 | E20: 60 | F20: 78 | G20: =AVERAGE(F35,G35)*G21 -> 86.45 | H20: =AVERAGE(G35,H35)*H21 -> 86.45 | I20: =AVERAGE(H35,I35)*I21 -> 86.45 | J20: =AVERAGE(I35,J35)*J21 -> 86.45 | K20: =AVERAGE(J35,K35)*K21 -> 86.45
A21: Interest rate on average debt | C21: =C20/AVERAGE(B35,C35) -> 0.041637752 | D21: =D20/AVERAGE(C35,D35) -> 0.049792531 | E21: =E20/AVERAGE(D35,E35) -> 0.056710775 | F21: =F20/AVERAGE(E35,F35) -> 0.06446281 | G21: 0.07 | H21: 0.07 | I21: 0.07 | J21: 0.07 | K21: 0.07 | L21: FY26 book rate ~6.4% looks low partly because interest on CWIP is capitalised (Screener flag). Forecast 7.0%.
A22: Profit before tax | B22: 129 | C22: 177 | D22: 189 | E22: 166 | F22: 115 | G22: =G18+G19-G20 -> 202.4845 | H22: =H18+H19-H20 -> 187.94227 | I22: =I18+I19-I20 -> 232.71712 | J22: =J18+J19-J20 -> 265.40192 | K22: =K18+K19-K20 -> 298.24781 | L22: History = reported (EBIT + OI - interest differs by <=1 from rounding).
A23: Tax | B23: 38 | C23: 49 | D23: 54 | E23: 43 | F23: 16 | G23: =G22*G24 -> 50.965349 | H23: =H22*H24 -> 47.305069 | I23: =I22*I24 -> 58.574898 | J23: =J22*J24 -> 66.801663 | K23: =K22*K24 -> 75.068974
A24: Effective tax rate | B24: =B23/B22 -> 0.29457364 | C24: =C23/C22 -> 0.27683616 | D24: =D23/D22 -> 0.28571429 | E24: =E23/E22 -> 0.25903614 | F24: =F23/F22 -> 0.13913043 | G24: 0.2517 | H24: 0.2517 | I24: 0.2517 | J24: 0.2517 | K24: 0.2517 | L24: FY26 14%, Q1FY27 1%: check the deferred-tax note in the AR. Forecast uses 25.17% statutory rate (conservative).
A25: Net profit (PAT) | B25: =B22-B23 -> 91 | C25: =C22-C23 -> 128 | D25: =D22-D23 -> 135 | E25: =E22-E23 -> 123 | F25: =F22-F23 -> 99 | G25: =G22-G23 -> 151.51915 | H25: =H22-H23 -> 140.6372 | I25: =I22-I23 -> 174.14222 | ... K25: =K22-K23 -> 223.17884
A26: PAT growth | C26: =C25/B25-1 -> 0.40659341 | D26: =D25/C25-1 -> 0.0546875 | E26: =E25/D25-1 -> -0.088888889 | F26: =F25/E25-1 -> -0.19512195 | G26: =G25/F25-1 -> 0.53049648 | H26: =H25/G25-1 -> -0.071818979 | I26: =I25/H25-1 -> 0.23823723 | J26: =J25/I25-1 -> 0.14044864 | K26: =K25/J25-1 -> 0.12375906
A27: EPS (Rs) | B27: =B25/DCF!$B$5 -> 18.879668 | C27: =C25/DCF!$B$5 -> 26.556017 | D27: =D25/DCF!$B$5 -> 28.008299 | E27: =E25/DCF!$B$5 -> 25.518672 | F27: =F25/DCF!$B$5 -> 20.539419 | G27: =G25/DCF!$B$5 -> 31.435509 | H27: =H25/DCF!$B$5 -> 29.177842 | I27: =I25/DCF!$B$5 -> 36.129091 | ... K27: =K25/DCF!$B$5 -> 46.302663 | L27: Current share count (4.82cr) used for all years.
A28: BALANCE SHEET & CASH FLOW
A29: Net fixed assets + CWIP | B29: 744 | C29: 867 | D29: 1038 | E29: 1347 | F29: 1436 | G29: =F29+G30-G16 -> 1494.512 | H29: =G29+H30-H16 -> 1542.4553 | I29: =H29+I30-I16 -> 1586.8132 | J29: =I29+J30-J16 -> 1638.1751 | K29: =J29+K30-K16 -> 1696.9587 | L29: Net block + capital work-in-progress (FY26: 1,101 + 335).
A30: Capex | B30: 110 | C30: 200 | D30: 251 | E30: 403 | F30: 188 | G30: =G11*G31 -> 182.85 | H30: =H11*H31 -> 187.6041 | I30: =I11*I31 -> 198.44345 | J30: =J11*J31 -> 218.28779 | K30: =K11*K31 -> 237.93369 | L30: History = cash from operations less free cash flow (Screener).
A31: Capex % of revenue | B31: =B30/B11 -> 0.096491228 | C31: =C30/C11 -> 0.13679891 | D31: =D30/D11 -> 0.16058861 | E31: =E30/E11 -> 0.2642623 | F31: =F30/F11 -> 0.11823899 | G31: 0.1 | H31: 0.09 | I31: 0.085 | J31: 0.085 | K31: 0.085 | L31: FY22-26 average ~15% (expansion cycle). Forecast: cycle ends, but capex stays above D&A to support growth.
A32: Net working capital & other net assets | B32: 477 | C32: 540 | D32: 659 | E32: 727 | F32: 765 | G32: =G11*(G33+$E$7) -> 841.11 | H32: =H11*(H33+$E$7) -> 917.1756 | I32: =I11*(I33+$E$7) -> 980.5441 | J32: =J11*(J33+$E$7) -> 1052.9176 | K32: =K11*(K33+$E$7) -> 1119.688 | L32: Other assets less other liabilities (Screener BS). Includes cash, which Screener does not split out.
A33: NWC % of revenue (base input; delta added) | B33: =B32/B11 -> 0.41842105 | C33: =C32/C11 -> 0.36935705 | D33: =D32/D11 -> 0.42162508 | E33: =E32/E11 -> 0.47672131 | F33: =F32/F11 -> 0.48113208 | G33: 0.46 | H33: 0.44 | I33: 0.42 | J33: 0.41 | K33: 0.4 | L33: Rose from 37% (FY23) to 48% (FY26) as debtor days went 49->96. Base assumes partial normalisation.
A34: Investments | B34: 22 | C34: 22 | D34: 23 | E34: 4 | F34: 10 | G34: 10 | H34: 10 | I34: 10 | J34: 10 | K34: 10
A35: Borrowings | B35: 685 | C35: 756 | D35: 931 | E35: 1185 | F35: 1235 | G35: 1235 | H35: 1235 | I35: 1235 | J35: 1235 | K35: 1235 | L35: Held flat; surplus cash / funding gap shows in the balancing row.
A36: Dividends paid (forecast) | G36: =G25*$I$5 -> 15.151915 | H36: =H25*$I$5 -> 14.06372 | I36: =I25*$I$5 -> 17.414222 | J36: =J25*$I$5 -> 19.860026 | K36: =K25*$I$5 -> 22.317884
A37: Net worth | B37: 559 | C37: 673 | D37: 789 | E37: 893 | F37: 975 | G37: =F37+G25-G36 -> 1111.3672 | H37: =G37+H25-H36 -> 1237.9407 | I37: =H37+I25-I36 -> 1394.6687 | J37: =I37+J25-J36 -> 1573.4089 | K37: =J37+K25-K36 -> 1774.2699
A38: Surplus cash / (funding gap) - balancing item | B38: =B37+B35-B29-B32-B34 -> 1 | C38: =C37+C35-C29-C32-C34 -> 0 | D38: =D37+D35-D29-D32-D34 -> 0 | E38: =E37+E35-E29-E32-E34 -> 0 | F38: =F37+F35-F29-F32-F34 -> -1 | G38: =G37+G35-G29-G32-G34 -> 0.74523622 | H38: =H37+H35-H29-H32-H34 -> 3.3098468 | I38: =I37+I35-I29-I32-I34 -> 52.311399 | ... K38: =K37+K35-K29-K32-K34 -> 182.62325 | L38: History ~0 (rounding). Simplification: no interest earned on surplus / paid on gap.
A39: Cash from operations (reported) | B39: 150 | C39: 160 | D39: 149 | E39: 182 | F39: 228
A40: Free cash flow (reported: CFO - capex) | B40: =B39-B30 -> 40 | C40: =C39-C30 -> -40 | D40: =D39-D30 -> -102 | E40: =E39-E30 -> -221 | F40: =F39-F30 -> 40
A41: FREE CASH FLOW TO FIRM (FCFF)
...

Sheet DCF
A1: MMFL - DCF (FCFF), reverse DCF and sensitivities
A2: Valuation date 30-Sep-2026. Mid-period discounting; FY27E counts only the half-year after the valuation date.
A3: INPUTS & WACC
A4: CMP (Rs), 29-Sep-2026 | B4: 612
A5: Shares outstanding (crore) | B5: 4.82
A6: Market capitalisation (Rs cr) | B6: =B4*B5 -> 2949.84
A8: Risk-free rate (10Y G-sec, Sep-2026) | B8: 0.071
A9: Equity risk premium (India) | B9: 0.065
A10: Unlevered (asset) beta | B10: 1 | C10: Cyclical auto-component business; relevered at market D/E. Try 0.8-1.2.
A11: Borrowings FY26 (Rs cr) | B11: =Model!F35 -> 1235
A12: Statutory tax rate | B12: 0.2517
A13: Debt / equity (market values) | B13: =B11/B6 -> 0.41866678
A14: Levered beta = Bu x (1 + (1 - t) x D/E) | B14: =B10*(1+(1-B12)*B13) -> 1.3132883
A15: Cost of equity (CAPM) = Rf + B x ERP | B15: =B8+B14*B9 -> 0.15636374
A16: Pre-tax cost of debt | B16: 0.0875 | C16: A-rated corporate marginal borrowing cost; FY26 book rate is lower because some interest is capitalised.
A17: Post-tax cost of debt | B17: =B16*(1-B12) -> 0.06547625
A18: Weight of equity | B18: =B6/(B6+B11) -> 0.70488716
A19: Weight of debt | B19: =1-B18 -> 0.29511284
A20: WACC | B20: =B18*B15+B19*B17 -> 0.12954168
A21: Terminal growth (g) | B21: 0.06 | C21: Below nominal GDP growth (~10%): a mature auto supplier.
A22: Return on new invested capital in terminal period (RONIC) | B22: 0.15 | C22: Value-driver formula: reinvestment = g / RONIC. RONIC above WACC means growth adds value.
A24: INR crore unless stated | C24: FY27E | D24: FY28E | E24: FY29E | F24: FY30E | G24: FY31E
A25: FCFF (from Model) | C25: =Model!G44 -> 25.465186 | D25: =Model!H44 -> 67.849466 | E25: =Model!I44 -> 117.63691 | F25: =Model!J44 -> 126.08606 | G25: =Model!K44 -> 148.84597
A26: Fraction of year after valuation date | C26: 0.5 | D26: 1 | E26: 1 | F26: 1 | G26: 1
A27: FCFF to be valued | C27: =C25*C26 -> 12.732593 | D27: =D25*D26 -> 67.849466 | E27: =E25*E26 -> 117.63691 | F27: =F25*F26 -> 126.08606 | G27: =G25*G26 -> 148.84597
A28: Discount period (years, mid-period) | C28: 0.25 | D28: 1 | E28: 2 | F28: 3 | G28: 4
A29: Discount factor at WACC | C29: =1/(1+$B$20)^C28 -> 0.97000603 | D29: =1/(1+$B$20)^D28 -> 0.88531483 | E29: =1/(1+$B$20)^E28 -> 0.78378235 | F29: =1/(1+$B$20)^F28 -> 0.69389414 | G29: =1/(1+$B$20)^G28 -> 0.61431478
A30: PV of FCFF | C30: =C27*C29 -> 12.350692 | D30: =D27*D29 -> 60.068138 | E30: =E27*E29 -> 92.201733 | F30: =F27*F29 -> 87.490381 | G30: =G27*G29 -> 91.438278
A32: TERMINAL VALUE (value-driver formula: TV = NOPAT x (1 - g/RONIC) / (WACC - g))
A33: NOPAT FY32E = NOPAT FY31E x (1 + g) | B33: =Model!K42*(1+B21) -> 290.86397
A34: Reinvestment rate = g / RONIC | B34: =B21/B22 -> 0.4
A35: FCFF FY32E = NOPAT x (1 - reinvestment rate) | B35: =B33*(1-B34) -> 174.51838
A36: Terminal value at Mar-31 = FCFF FY32E / (WACC - g) | B36: =B35/(B20-B21) -> 2509.551
A37: Discount factor (4.5 years) | B37: =1/(1+B20)^4.5 -> 0.57801596
A38: PV of terminal value | B38: =B36*B37 -> 1450.5605
A39: Implied exit EV/EBITDA on FY31E (sanity check) | B39: =B36/Model!K13 -> 4.597528
A41: VALUATION
A42: Sum of PV of FCFF | B42: =SUM(C30:G30) -> 343.54922
A43: PV of terminal value | B43: =B38 -> 1450.5605
A44: Enterprise value (EV) | B44: =B42+B43 -> 1794.1097
...

Sheet Quarterly
A1: MMFL - quarterly results tracker (consolidated, Rs crore)
A3: Quarter | B3: Jun-23 | C3: Sep-23 | D3: Dec-23 | E3: Mar-24 | F3: Jun-24 | G3: Sep-24 | H3: Dec-24 | I3: Mar-25 | J3: Jun-25 | K3: Sep-25 | L3: Dec-25 | M3: Mar-26 | N3: Jun-26 | P3: TTM
A4: Revenue | B4: 370 | C4: 397 | D4: 399 | E4: 398 | F4: 382 | G4: 398 | H4: 374 | I4: 371 | J4: 362 | K4: 385 | L4: 414 | M4: 430 | N4: 420 | P4: =SUM(K4:N4) -> 1649
A5: EBITDA | B5: 65 | C5: 75 | D5: 75 | E5: 78 | F5: 73 | G5: 77 | H5: 73 | I5: 73 | J5: 63 | K5: 67 | L5: 69 | M5: 81 | N5: 75 | P5: =SUM(K5:N5) -> 292
A6: EBITDA margin | B6: =B5/B4 -> 0.17567568 | C6: =C5/C4 -> 0.18891688 | D6: =D5/D4 -> 0.18796992 | E6: =E5/E4 -> 0.1959799 | F6: =F5/F4 -> 0.19109948 | G6: =G5/G4 -> 0.19346734 | H6: =H5/H4 -> 0.19518717 | I6: =I5/I4 -> 0.1967655 | ... N6: =N5/N4 -> 0.17857143 | P6: =P5/P4 -> 0.17707702
A7: Revenue growth YoY | F7: =F4/B4-1 -> 0.032432432 | G7: =G4/C4-1 -> 0.0025188917 | H7: =H4/D4-1 -> -0.062656642 | I7: =I4/E4-1 -> -0.067839196 | J7: =J4/F4-1 -> -0.052356021 | K7: =K4/G4-1 -> -0.032663317 | L7: =L4/H4-1 -> 0.10695187 | M7: =M4/I4-1 -> 0.15902965 | N7: =N4/J4-1 -> 0.16022099
A8: EBITDA growth YoY | F8: =F5/B5-1 -> 0.12307692 | G8: =G5/C5-1 -> 0.026666667 | H8: =H5/D5-1 -> -0.026666667 | I8: =I5/E5-1 -> -0.064102564 | J8: =J5/F5-1 -> -0.1369863 | K8: =K5/G5-1 -> -0.12987013 | L8: =L5/H5-1 -> -0.054794521 | M8: =M5/I5-1 -> 0.10958904 | N8: =N5/J5-1 -> 0.19047619
A10: FY27E check
A11: FY27E revenue in model (active scenario) | B11: =Model!G11 -> 1828.5
A12: Revenue still needed in Q2-Q4 FY27 | B12: =B11-N4 -> 1408.5
A13: Implied average per remaining quarter | B13: =B12/3 -> 469.5
A14: Implied quarterly growth vs Q1FY27 run-rate | B14: =B13/N4-1 -> 0.11785714
A16: Q1FY27 memo: PBT Rs91cr and PAT Rs90cr include a one-off other income of Rs63cr; tax rate ~1%. Strip it out when judging the run-rate.

Sheet Reverse_DCF_Grid
A1: Reverse DCF map: value per share (Rs) for any revenue CAGR x steady EBITDA margin
A2: Live formulas. Each cell re-runs the 5-year FCFF + terminal value with a constant growth rate and margin (other drivers as on Model). Green = justifies the current price.
A4: Tax rate | B4: =DCF!B12 -> 0.2517
A5: FY26 revenue (Rs cr) | B5: =Model!F11 -> 1590
A6: FY26 net working capital (Rs cr) | B6: =Model!F32 -> 765
A7: Year index t | C7: 1 | D7: 2 | E7: 3 | F7: 4 | G7: 5
A8: Fraction of year valued | C8: =DCF!C26 -> 0.5 | D8: =DCF!D26 -> 1 | E8: =DCF!E26 -> 1 | F8: =DCF!F26 -> 1 | G8: =DCF!G26 -> 1
A9: D&A % of revenue | C9: =Model!G17 -> 0.068 | D9: =Model!H17 -> 0.067 | E9: =Model!I17 -> 0.066 | F9: =Model!J17 -> 0.065 | G9: =Model!K17 -> 0.064
A10: Capex % of revenue | C10: =Model!G31 -> 0.1 | D10: =Model!H31 -> 0.09 | E10: =Model!I31 -> 0.085 | F10: =Model!J31 -> 0.085 | G10: =Model!K31 -> 0.085
A11: NWC % of revenue (active scenario) | C11: =Model!G33+Model!$E$7 -> 0.46 | D11: =Model!H33+Model!$E$7 -> 0.44 | E11: =Model!I33+Model!$E$7 -> 0.42 | F11: =Model!J33+Model!$E$7 -> 0.41 | G11: =Model!K33+Model!$E$7 -> 0.4
A12: Prior-year NWC % of revenue | C12: =$B$6/$B$5 -> 0.48113208 | D12: =C11 -> 0.46 | E12: =D11 -> 0.44 | F12: =E11 -> 0.42 | G12: =F11 -> 0.41
A13: Discount period (years) | C13: =DCF!C28 -> 0.25 | D13: =DCF!D28 -> 1 | E13: =DCF!E28 -> 2 | F13: =DCF!F28 -> 3 | G13: =DCF!G28 -> 4
A14: WACC for grid A (= DCF sheet) | B14: =DCF!B20 -> 0.12954168
A15: WACC for grid B (lower discount rate) | B15: 0.11
A16: Terminal growth g | B16: =DCF!B21 -> 0.06
A17: RONIC | B17: =DCF!B22 -> 0.15
A18: Borrowings | B18: =DCF!B46 -> 1235
A19: Investments | B19: =DCF!B47 -> 10
A20: Shares (crore) | B20: =DCF!B5 -> 4.82
A21: CMP (Rs) | B21: =DCF!B4 -> 612
A23: GRID A: at the model WACC
B24: CAGR \ margin | C24: 0.16 | D24: 0.18 | E24: 0.2 | F24: 0.22 | G24: 0.24 | H24: 0.26
B25: 0.06 | C25: =(SUMPRODUCT($C$8:$G$8,1/(1+$B$14)^$C$13:$G$13,$B$5*(1+$B25)^$C$7:$G$7*((C$24-$C$9:$G$9)*(1-$B$4)+$C$9:$G$9-$C$10:$G$10-$C$11:$G$11)+$B$5*(1+$B25)^($C$7:$G$7-1)*$C$12:$G$12)+$B$5*(1+$B25)^5*(C$24-$G$9)*(1-$B$4)*(1+$B$16)*(1-$B$16/$B$17)/($B$14-$B$16)/(1+$B$14)^4.5-$B$18+$B$19)/$B$20 -> -32.701425 | D25: =(SUMPRODUCT($C$8:$G$8,1/(1+$B$14)^$C$13:$G$13,$B$5*(1+$B25)^$C$7:$G$7*((D$24-$C$9:$G$9)*(1-$B$4)+$C$9:$G$9-$C$10:$G$10-$C$11:$G$11)+$B$5*(1+$B25)^($C$7:$G$7-1)*$C$12:$G$12)+$B$5*(1+$B25)^5*(D$24-$G$9)*(1-$B$4)*(1+$B$16)*(1-$B$16/$B$17)/($B$14-$B$16)/(1+$B$14)^4.5-$B$18+$B$19)/$B$20 -> 22.664712 | E25: =(SUMPRODUCT($C$8:$G$8,1/(1+$B$14)^$C$13:$G$13,$B$5*(1+$B25)^$C$7:$G$7*((E$24-$C$9:$G$9)*(1-$B$4)+$C$9:$G$9-$C$10:$G$10-$C$11:$G$11)+$B$5*(1+$B25)^($C$7:$G$7-1)*$C$12:$G$12)+$B$5*(1+$B25)^5*(E$24-$G$9)*(1-$B$4)*(1+$B$16)*(1-$B$16/$B$17)/($B$14-$B$16)/(1+$B$14)^4.5-$B$18+$B$19)/$B$20 -> 78.030849 | F25: =(SUMPRODUCT($C$8:$G$8,1/(1+$B$14)^$C$13:$G$13,$B$5*(1+$B25)^$C$7:$G$7*((F$24-$C$9:$G$9)*(1-$B$4)+$C$9:$G$9-$C$10:$G$10-$C$11:$G$11)+$B$5*(1+$B25)^($C$7:$G$7-1)*$C$12:$G$12)+$B$5*(1+$B25)^5*(F$24-$G$9)*(1-$B$4)*(1+$B$16)*(1-$B$16/$B$17)/($B$14-$B$16)/(1+$B$14)^4.5-$B$18+$B$19)/$B$20 -> 133.39699 | G25: =(SUMPRODUCT($C$8:$G$8,1/(1+$B$14)^$C$13:$G$13,$B$5*(1+$B25)^$C$7:$G$7*((G$24-$C$9:$G$9)*(1-$B$4)+$C$9:$G$9-$C$10:$G$10-$C$11:$G$11)+$B$5*(1+$B25)^($C$7:$G$7-1)*$C$12:$G$12)+$B$5*(1+$B25)^5*(G$24-$G$9)*(1-$B$4)*(1+$B$16)*(1-$B$16/$B$17)/($B$14-$B$16)/(1+$B$14)^4.5-$B$18+$B$19)/$B$20 -> 188.76312 | H25: =(SUMPRODUCT($C$8:$G$8,1/(1+$B$14)^$C$13:$G$13,$B$5*(1+$B25)^$C$7:$G$7*((H$24-$C$9:$G$9)*(1-$B$4)+$C$9:$G$9-$C$10:$G$10-$C$11:$G$11)+$B$5*(1+$B25)^($C$7:$G$7-1)*$C$12:$G$12)+$B$5*(1+$B25)^5*(H$24-$G$9)*(1-$B$4)*(1+$B$16)*(1-$B$16/$B$17)/($B$14-$B$16)/(1+$B$14)^4.5-$B$18+$B$19)/$B$20 -> 244.12926
B26: 0.08 | C26: =(SUMPRODUCT($C$8:$G$8,1/(1+$B$14)^$C$13:$G$13,$B$5*(1+$B26)^$C$7:$G$7*((C$24-$C$9:$G$9)*(1-$B$4)+$C$9:$G$9-$C$10:$G$10-$C$11:$G$11)+$B$5*(1+$B26)^($C$7:$G$7-1)*$C$12:$G$12)+$B$5*(1+$B26)^5*(C$24-$G$9)*(1-$B$4)*(1+$B$16)*(1-$B$16/$B$17)/($B$14-$B$16)/(1+$B$14)^4.5-$B$18+$B$19)/$B$20 -> -24.122554 | D26: =(SUMPRODUCT($C$8:$G$8,1/(1+$B$14)^$C$13:$G$13,$B$5*(1+$B26)^$C$7:$G$7*((D$24-$C$9:$G$9)*(1-$B$4)+$C$9:$G$9-$C$10:$G$10-$C$11:$G$11)+$B$5*(1+$B26)^($C$7:$G$7-1)*$C$12:$G$12)+$B$5*(1+$B26)^5*(D$24-$G$9)*(1-$B$4)*(1+$B$16)*(1-$B$16/$B$17)/($B$14-$B$16)/(1+$B$14)^4.5-$B$18+$B$19)/$B$20 -> 35.899241 | E26: =(SUMPRODUCT($C$8:$G$8,1/(1+$B$14)^$C$13:$G$13,$B$5*(1+$B26)^$C$7:$G$7*((E$24-$C$9:$G$9)*(1-$B$4)+$C$9:$G$9-$C$10:$G$10-$C$11:$G$11)+$B$5*(1+$B26)^($C$7:$G$7-1)*$C$12:$G$12)+$B$5*(1+$B26)^5*(E$24-$G$9)*(1-$B$4)*(1+$B$16)*(1-$B$16/$B$17)/($B$14-$B$16)/(1+$B$14)^4.5-$B$18+$B$19)/$B$20 -> 95.921037 | F26: =(SUMPRODUCT($C$8:$G$8,1/(1+$B$14)^$C$13:$G$13,$B$5*(1+$B26)^$C$7:$G$7*((F$24-$C$9:$G$9)*(1-$B$4)+$C$9:$G$9-$C$10:$G$10-$C$11:$G$11)+$B$5*(1+$B26)^($C$7:$G$7-1)*$C$12:$G$12)+$B$5*(1+$B26)^5*(F$24-$G$9)*(1-$B$4)*(1+$B$16)*(1-$B$16/$B$17)/($B$14-$B$16)/(1+$B$14)^4.5-$B$18+$B$19)/$B$20 -> 155.94283 | G26: =(SUMPRODUCT($C$8:$G$8,1/(1+$B$14)^$C$13:$G$13,$B$5*(1+$B26)^$C$7:$G$7*((G$24-$C$9:$G$9)*(1-$B$4)+$C$9:$G$9-$C$10:$G$10-$C$11:$G$11)+$B$5*(1+$B26)^($C$7:$G$7-1)*$C$12:$G$12)+$B$5*(1+$B26)^5*(G$24-$G$9)*(1-$B$4)*(1+$B$16)*(1-$B$16/$B$17)/($B$14-$B$16)/(1+$B$14)^4.5-$B$18+$B$19)/$B$20 -> 215.96463 | H26: =(SUMPRODUCT($C$8:$G$8,1/(1+$B$14)^$C$13:$G$13,$B$5*(1+$B26)^$C$7:$G$7*((H$24-$C$9:$G$9)*(1-$B$4)+$C$9:$G$9-$C$10:$G$10-$C$11:$G$11)+$B$5*(1+$B26)^($C$7:$G$7-1)*$C$12:$G$12)+$B$5*(1+$B26)^5*(H$24-$G$9)*(1-$B$4)*(1+$B$16)*(1-$B$16/$B$17)/($B$14-$B$16)/(1+$B$14)^4.5-$B$18+$B$19)/$B$20 -> 275.98642
B27: 0.1 | C27: =(SUMPRODUCT($C$8:$G$8,1/(1+$B$14)^$C$13:$G$13,$B$5*(1+$B27)^$C$7:$G$7*((C$24-$C$9:$G$9)*(1-$B$4)+$C$9:$G$9-$C$10:$G$10-$C$11:$G$11)+$B$5*(1+$B27)^($C$7:$G$7-1)*$C$12:$G$12)+$B$5*(1+$B27)^5*(C$24-$G$9)*(1-$B$4)*(1+$B$16)*(1-$B$16/$B$17)/($B$14-$B$16)/(1+$B$14)^4.5-$B$18+$B$19)/$B$20 -> -14.987783 | D27: =(SUMPRODUCT($C$8:$G$8,1/(1+$B$14)^$C$13:$G$13,$B$5*(1+$B27)^$C$7:$G$7*((D$24-$C$9:$G$9)*(1-$B$4)+$C$9:$G$9-$C$10:$G$10-$C$11:$G$11)+$B$5*(1+$B27)^($C$7:$G$7-1)*$C$12:$G$12)+$B$5*(1+$B27)^5*(D$24-$G$9)*(1-$B$4)*(1+$B$16)*(1-$B$16/$B$17)/($B$14-$B$16)/(1+$B$14)^4.5-$B$18+$B$19)/$B$20 -> 50.015999 | E27: =(SUMPRODUCT($C$8:$G$8,1/(1+$B$14)^$C$13:$G$13,$B$5*(1+$B27)^$C$7:$G$7*((E$24-$C$9:$G$9)*(1-$B$4)+$C$9:$G$9-$C$10:$G$10-$C$11:$G$11)+$B$5*(1+$B27)^($C$7:$G$7-1)*$C$12:$G$12)+$B$5*(1+$B27)^5*(E$24-$G$9)*(1-$B$4)*(1+$B$16)*(1-$B$16/$B$17)/($B$14-$B$16)/(1+$B$14)^4.5-$B$18+$B$19)/$B$20 -> 115.01978 | F27: =(SUMPRODUCT($C$8:$G$8,1/(1+$B$14)^$C$13:$G$13,$B$5*(1+$B27)^$C$7:$G$7*((F$24-$C$9:$G$9)*(1-$B$4)+$C$9:$G$9-$C$10:$G$10-$C$11:$G$11)+$B$5*(1+$B27)^($C$7:$G$7-1)*$C$12:$G$12)+$B$5*(1+$B27)^5*(F$24-$G$9)*(1-$B$4)*(1+$B$16)*(1-$B$16/$B$17)/($B$14-$B$16)/(1+$B$14)^4.5-$B$18+$B$19)/$B$20 -> 180.02356 | G27: =(SUMPRODUCT($C$8:$G$8,1/(1+$B$14)^$C$13:$G$13,$B$5*(1+$B27)^$C$7:$G$7*((G$24-$C$9:$G$9)*(1-$B$4)+$C$9:$G$9-$C$10:$G$10-$C$11:$G$11)+$B$5*(1+$B27)^($C$7:$G$7-1)*$C$12:$G$12)+$B$5*(1+$B27)^5*(G$24-$G$9)*(1-$B$4)*(1+$B$16)*(1-$B$16/$B$17)/($B$14-$B$16)/(1+$B$14)^4.5-$B$18+$B$19)/$B$20 -> 245.02735 | H27: =(SUMPRODUCT($C$8:$G$8,1/(1+$B$14)^$C$13:$G$13,$B$5*(1+$B27)^$C$7:$G$7*((H$24-$C$9:$G$9)*(1-$B$4)+$C$9:$G$9-$C$10:$G$10-$C$11:$G$11)+$B$5*(1+$B27)^($C$7:$G$7-1)*$C$12:$G$12)+$B$5*(1+$B27)^5*(H$24-$G$9)*(1-$B$4)*(1+$B$16)*(1-$B$16/$B$17)/($B$14-$B$16)/(1+$B$14)^4.5-$B$18+$B$19)/$B$20 -> 310.03113
B28: 0.12 | C28: =(SUMPRODUCT($C$8:$G$8,1/(1+$B$14)^$C$13:$G$13,$B$5*(1+$B28)^$C$7:$G$7*((C$24-$C$9:$G$9)*(1-$B$4)+$C$9:$G$9-$C$10:$G$10-$C$11:$G$11)+$B$5*(1+$B28)^($C$7:$G$7-1)*$C$12:$G$12)+$B$5*(1+$B28)^5*(C$24-$G$9)*(1-$B$4)*(1+$B$16)*(1-$B$16/$B$17)/($B$14-$B$16)/(1+$B$14)^4.5-$B$18+$B$19)/$B$20 -> -5.2657877 | D28: =(SUMPRODUCT($C$8:$G$8,1/(1+$B$14)^$C$13:$G$13,$B$5*(1+$B28)^$C$7:$G$7*((D$24-$C$9:$G$9)*(1-$B$4)+$C$9:$G$9-$C$10:$G$10-$C$11:$G$11)+$B$5*(1+$B28)^($C$7:$G$7-1)*$C$12:$G$12)+$B$5*(1+$B28)^5*(D$24-$G$9)*(1-$B$4)*(1+$B$16)*(1-$B$16/$B$17)/($B$14-$B$16)/(1+$B$14)^4.5-$B$18+$B$19)/$B$20 -> 65.063828 | E28: =(SUMPRODUCT($C$8:$G$8,1/(1+$B$14)^$C$13:$G$13,$B$5*(1+$B28)^$C$7:$G$7*((E$24-$C$9:$G$9)*(1-$B$4)+$C$9:$G$9-$C$10:$G$10-$C$11:$G$11)+$B$5*(1+$B28)^($C$7:$G$7-1)*$C$12:$G$12)+$B$5*(1+$B28)^5*(E$24-$G$9)*(1-$B$4)*(1+$B$16)*(1-$B$16/$B$17)/($B$14-$B$16)/(1+$B$14)^4.5-$B$18+$B$19)/$B$20 -> 135.39344 | F28: =(SUMPRODUCT($C$8:$G$8,1/(1+$B$14)^$C$13:$G$13,$B$5*(1+$B28)^$C$7:$G$7*((F$24-$C$9:$G$9)*(1-$B$4)+$C$9:$G$9-$C$10:$G$10-$C$11:$G$11)+$B$5*(1+$B28)^($C$7:$G$7-1)*$C$12:$G$12)+$B$5*(1+$B28)^5*(F$24-$G$9)*(1-$B$4)*(1+$B$16)*(1-$B$16/$B$17)/($B$14-$B$16)/(1+$B$14)^4.5-$B$18+$B$19)/$B$20 -> 205.72306 | G28: =(SUMPRODUCT($C$8:$G$8,1/(1+$B$14)^$C$13:$G$13,$B$5*(1+$B28)^$C$7:$G$7*((G$24-$C$9:$G$9)*(1-$B$4)+$C$9:$G$9-$C$10:$G$10-$C$11:$G$11)+$B$5*(1+$B28)^($C$7:$G$7-1)*$C$12:$G$12)+$B$5*(1+$B28)^5*(G$24-$G$9)*(1-$B$4)*(1+$B$16)*(1-$B$16/$B$17)/($B$14-$B$16)/(1+$B$14)^4.5-$B$18+$B$19)/$B$20 -> 276.05268 | H28: =(SUMPRODUCT($C$8:$G$8,1/(1+$B$14)^$C$13:$G$13,$B$5*(1+$B28)^$C$7:$G$7*((H$24-$C$9:$G$9)*(1-$B$4)+$C$9:$G$9-$C$10:$G$10-$C$11:$G$11)+$B$5*(1+$B28)^($C$7:$G$7-1)*$C$12:$G$12)+$B$5*(1+$B28)^5*(H$24-$G$9)*(1-$B$4)*(1+$B$16)*(1-$B$16/$B$17)/($B$14-$B$16)/(1+$B$14)^4.5-$B$18+$B$19)/$B$20 -> 346.38229
B29: 0.14 | C29: =(SUMPRODUCT($C$8:$G$8,1/(1+$B$14)^$C$13:$G$13,$B$5*(1+$B29)^$C$7:$G$7*((C$24-$C$9:$G$9)*(1-$B$4)+$C$9:$G$9-$C$10:$G$10-$C$11:$G$11)+$B$5*(1+$B29)^($C$7:$G$7-1)*$C$12:$G$12)+$B$5*(1+$B29)^5*(C$24-$G$9)*(1-$B$4)*(1+$B$16)*(1-$B$16/$B$17)/($B$14-$B$16)/(1+$B$14)^4.5-$B$18+$B$19)/$B$20 -> 5.0759129 | D29: =(SUMPRODUCT($C$8:$G$8,1/(1+$B$14)^$C$13:$G$13,$B$5*(1+$B29)^$C$7:$G$7*((D$24-$C$9:$G$9)*(1-$B$4)+$C$9:$G$9-$C$10:$G$10-$C$11:$G$11)+$B$5*(1+$B29)^($C$7:$G$7-1)*$C$12:$G$12)+$B$5*(1+$B29)^5*(D$24-$G$9)*(1-$B$4)*(1+$B$16)*(1-$B$16/$B$17)/($B$14-$B$16)/(1+$B$14)^4.5-$B$18+$B$19)/$B$20 -> 81.093354 | E29: =(SUMPRODUCT($C$8:$G$8,1/(1+$B$14)^$C$13:$G$13,$B$5*(1+$B29)^$C$7:$G$7*((E$24-$C$9:$G$9)*(1-$B$4)+$C$9:$G$9-$C$10:$G$10-$C$11:$G$11)+$B$5*(1+$B29)^($C$7:$G$7-1)*$C$12:$G$12)+$B$5*(1+$B29)^5*(E$24-$G$9)*(1-$B$4)*(1+$B$16)*(1-$B$16/$B$17)/($B$14-$B$16)/(1+$B$14)^4.5-$B$18+$B$19)/$B$20 -> 157.11079 | F29: =(SUMPRODUCT($C$8:$G$8,1/(1+$B$14)^$C$13:$G$13,$B$5*(1+$B29)^$C$7:$G$7*((F$24-$C$9:$G$9)*(1-$B$4)+$C$9:$G$9-$C$10:$G$10-$C$11:$G$11)+$B$5*(1+$B29)^($C$7:$G$7-1)*$C$12:$G$12)+$B$5*(1+$B29)^5*(F$24-$G$9)*(1-$B$4)*(1+$B$16)*(1-$B$16/$B$17)/($B$14-$B$16)/(1+$B$14)^4.5-$B$18+$B$19)/$B$20 -> 233.12824 | G29: =(SUMPRODUCT($C$8:$G$8,1/(1+$B$14)^$C$13:$G$13,$B$5*(1+$B29)^$C$7:$G$7*((G$24-$C$9:$G$9)*(1-$B$4)+$C$9:$G$9-$C$10:$G$10-$C$11:$G$11)+$B$5*(1+$B29)^($C$7:$G$7-1)*$C$12:$G$12)+$B$5*(1+$B29)^5*(G$24-$G$9)*(1-$B$4)*(1+$B$16)*(1-$B$16/$B$17)/($B$14-$B$16)/(1+$B$14)^4.5-$B$18+$B$19)/$B$20 -> 309.14568 | H29: =(SUMPRODUCT($C$8:$G$8,1/(1+$B$14)^$C$13:$G$13,$B$5*(1+$B29)^$C$7:$G$7*((H$24-$C$9:$G$9)*(1-$B$4)+$C$9:$G$9-$C$10:$G$10-$C$11:$G$11)+$B$5*(1+$B29)^($C$7:$G$7-1)*$C$12:$G$12)+$B$5*(1+$B29)^5*(H$24-$G$9)*(1-$B$4)*(1+$B$16)*(1-$B$16/$B$17)/($B$14-$B$16)/(1+$B$14)^4.5-$B$18+$B$19)/$B$20 -> 385.16312
B30: 0.16 | C30: =(SUMPRODUCT($C$8:$G$8,1/(1+$B$14)^$C$13:$G$13,$B$5*(1+$B30)^$C$7:$G$7*((C$24-$C$9:$G$9)*(1-$B$4)+$C$9:$G$9-$C$10:$G$10-$C$11:$G$11)+$B$5*(1+$B30)^($C$7:$G$7-1)*$C$12:$G$12)+$B$5*(1+$B30)^5*(C$24-$G$9)*(1-$B$4)*(1+$B$16)*(1-$B$16/$B$17)/($B$14-$B$16)/(1+$B$14)^4.5-$B$18+$B$19)/$B$20 -> 16.070974 | D30: =(SUMPRODUCT($C$8:$G$8,1/(1+$B$14)^$C$13:$G$13,$B$5*(1+$B30)^$C$7:$G$7*((D$24-$C$9:$G$9)*(1-$B$4)+$C$9:$G$9-$C$10:$G$10-$C$11:$G$11)+$B$5*(1+$B30)^($C$7:$G$7-1)*$C$12:$G$12)+$B$5*(1+$B30)^5*(D$24-$G$9)*(1-$B$4)*(1+$B$16)*(1-$B$16/$B$17)/($B$14-$B$16)/(1+$B$14)^4.5-$B$18+$B$19)/$B$20 -> 98.157017 | E30: =(SUMPRODUCT($C$8:$G$8,1/(1+$B$14)^$C$13:$G$13,$B$5*(1+$B30)^$C$7:$G$7*((E$24-$C$9:$G$9)*(1-$B$4)+$C$9:$G$9-$C$10:$G$10-$C$11:$G$11)+$B$5*(1+$B30)^($C$7:$G$7-1)*$C$12:$G$12)+$B$5*(1+$B30)^5*(E$24-$G$9)*(1-$B$4)*(1+$B$16)*(1-$B$16/$B$17)/($B$14-$B$16)/(1+$B$14)^4.5-$B$18+$B$19)/$B$20 -> 180.24306 | F30: =(SUMPRODUCT($C$8:$G$8,1/(1+$B$14)^$C$13:$G$13,$B$5*(1+$B30)^$C$7:$G$7*((F$24-$C$9:$G$9)*(1-$B$4)+$C$9:$G$9-$C$10:$G$10-$C$11:$G$11)+$B$5*(1+$B30)^($C$7:$G$7-1)*$C$12:$G$12)+$B$5*(1+$B30)^5*(F$24-$G$9)*(1-$B$4)*(1+$B$16)*(1-$B$16/$B$17)/($B$14-$B$16)/(1+$B$14)^4.5-$B$18+$B$19)/$B$20 -> 262.3291 | G30: =(SUMPRODUCT($C$8:$G$8,1/(1+$B$14)^$C$13:$G$13,$B$5*(1+$B30)^$C$7:$G$7*((G$24-$C$9:$G$9)*(1-$B$4)+$C$9:$G$9-$C$10:$G$10-$C$11:$G$11)+$B$5*(1+$B30)^($C$7:$G$7-1)*$C$12:$G$12)+$B$5*(1+$B30)^5*(G$24-$G$9)*(1-$B$4)*(1+$B$16)*(1-$B$16/$B$17)/($B$14-$B$16)/(1+$B$14)^4.5-$B$18+$B$19)/$B$20 -> 344.41514 | H30: =(SUMPRODUCT($C$8:$G$8,1/(1+$B$14)^$C$13:$G$13,$B$5*(1+$B30)^$C$7:$G$7*((H$24-$C$9:$G$9)*(1-$B$4)+$C$9:$G$9-$C$10:$G$10-$C$11:$G$11)+$B$5*(1+$B30)^($C$7:$G$7-1)*$C$12:$G$12)+$B$5*(1+$B30)^5*(H$24-$G$9)*(1-$B$4)*(1+$B$16)*(1-$B$16/$B$17)/($B$14-$B$16)/(1+$B$14)^4.5-$B$18+$B$19)/$B$20 -> 426.50119
B31: 0.18 | C31: =(SUMPRODUCT($C$8:$G$8,1/(1+$B$14)^$C$13:$G$13,$B$5*(1+$B31)^$C$7:$G$7*((C$24-$C$9:$G$9)*(1-$B$4)+$C$9:$G$9-$C$10:$G$10-$C$11:$G$11)+$B$5*(1+$B31)^($C$7:$G$7-1)*$C$12:$G$12)+$B$5*(1+$B31)^5*(C$24-$G$9)*(1-$B$4)*(1+$B$16)*(1-$B$16/$B$17)/($B$14-$B$16)/(1+$B$14)^4.5-$B$18+$B$19)/$B$20 -> 27.75425 | D31: =(SUMPRODUCT($C$8:$G$8,1/(1+$B$14)^$C$13:$G$13,$B$5*(1+$B31)^$C$7:$G$7*((D$24-$C$9:$G$9)*(1-$B$4)+$C$9:$G$9-$C$10:$G$10-$C$11:$G$11)+$B$5*(1+$B31)^($C$7:$G$7-1)*$C$12:$G$12)+$B$5*(1+$B31)^5*(D$24-$G$9)*(1-$B$4)*(1+$B$16)*(1-$B$16/$B$17)/($B$14-$B$16)/(1+$B$14)^4.5-$B$18+$B$19)/$B$20 -> 116.30911 | E31: =(SUMPRODUCT($C$8:$G$8,1/(1+$B$14)^$C$13:$G$13,$B$5*(1+$B31)^$C$7:$G$7*((E$24-$C$9:$G$9)*(1-$B$4)+$C$9:$G$9-$C$10:$G$10-$C$11:$G$11)+$B$5*(1+$B31)^($C$7:$G$7-1)*$C$12:$G$12)+$B$5*(1+$B31)^5*(E$24-$G$9)*(1-$B$4)*(1+$B$16)*(1-$B$16/$B$17)/($B$14-$B$16)/(1+$B$14)^4.5-$B$18+$B$19)/$B$20 -> 204.86396 | F31: =(SUMPRODUCT($C$8:$G$8,1/(1+$B$14)^$C$13:$G$13,$B$5*(1+$B31)^$C$7:$G$7*((F$24-$C$9:$G$9)*(1-$B$4)+$C$9:$G$9-$C$10:$G$10-$C$11:$G$11)+$B$5*(1+$B31)^($C$7:$G$7-1)*$C$12:$G$12)+$B$5*(1+$B31)^5*(F$24-$G$9)*(1-$B$4)*(1+$B$16)*(1-$B$16/$B$17)/($B$14-$B$16)/(1+$B$14)^4.5-$B$18+$B$19)/$B$20 -> 293.41882 | G31: =(SUMPRODUCT($C$8:$G$8,1/(1+$B$14)^$C$13:$G$13,$B$5*(1+$B31)^$C$7:$G$7*((G$24-$C$9:$G$9)*(1-$B$4)+$C$9:$G$9-$C$10:$G$10-$C$11:$G$11)+$B$5*(1+$B31)^($C$7:$G$7-1)*$C$12:$G$12)+$B$5*(1+$B31)^5*(G$24-$G$9)*(1-$B$4)*(1+$B$16)*(1-$B$16/$B$17)/($B$14-$B$16)/(1+$B$14)^4.5-$B$18+$B$19)/$B$20 -> 381.97367 | H31: =(SUMPRODUCT($C$8:$G$8,1/(1+$B$14)^$C$13:$G$13,$B$5*(1+$B31)^$C$7:$G$7*((H$24-$C$9:$G$9)*(1-$B$4)+$C$9:$G$9-$C$10:$G$10-$C$11:$G$11)+$B$5*(1+$B31)^($C$7:$G$7-1)*$C$12:$G$12)+$B$5*(1+$B31)^5*(H$24-$G$9)*(1-$B$4)*(1+$B$16)*(1-$B$16/$B$17)/($B$14-$B$16)/(1+$B$14)^4.5-$B$18+$B$19)/$B$20 -> 470.52853
B32: 0.2 | C32: =(SUMPRODUCT($C$8:$G$8,1/(1+$B$14)^$C$13:$G$13,$B$5*(1+$B32)^$C$7:$G$7*((C$24-$C$9:$G$9)*(1-$B$4)+$C$9:$G$9-$C$10:$G$10-$C$11:$G$11)+$B$5*(1+$B32)^($C$7:$G$7-1)*$C$12:$G$12)+$B$5*(1+$B32)^5*(C$24-$G$9)*(1-$B$4)*(1+$B$16)*(1-$B$16/$B$17)/($B$14-$B$16)/(1+$B$14)^4.5-$B$18+$B$19)/$B$20 -> 40.161809 | D32: =(SUMPRODUCT($C$8:$G$8,1/(1+$B$14)^$C$13:$G$13,$B$5*(1+$B32)^$C$7:$G$7*((D$24-$C$9:$G$9)*(1-$B$4)+$C$9:$G$9-$C$10:$G$10-$C$11:$G$11)+$B$5*(1+$B32)^($C$7:$G$7-1)*$C$12:$G$12)+$B$5*(1+$B32)^5*(D$24-$G$9)*(1-$B$4)*(1+$B$16)*(1-$B$16/$B$17)/($B$14-$B$16)/(1+$B$14)^4.5-$B$18+$B$19)/$B$20 -> 135.60579 | E32: =(SUMPRODUCT($C$8:$G$8,1/(1+$B$14)^$C$13:$G$13,$B$5*(1+$B32)^$C$7:$G$7*((E$24-$C$9:$G$9)*(1-$B$4)+$C$9:$G$9-$C$10:$G$10-$C$11:$G$11)+$B$5*(1+$B32)^($C$7:$G$7-1)*$C$12:$G$12)+$B$5*(1+$B32)^5*(E$24-$G$9)*(1-$B$4)*(1+$B$16)*(1-$B$16/$B$17)/($B$14-$B$16)/(1+$B$14)^4.5-$B$18+$B$19)/$B$20 -> 231.04977 | F32: =(SUMPRODUCT($C$8:$G$8,1/(1+$B$14)^$C$13:$G$13,$B$5*(1+$B32)^$C$7:$G$7*((F$24-$C$9:$G$9)*(1-$B$4)+$C$9:$G$9-$C$10:$G$10-$C$11:$G$11)+$B$5*(1+$B32)^($C$7:$G$7-1)*$C$12:$G$12)+$B$5*(1+$B32)^5*(F$24-$G$9)*(1-$B$4)*(1+$B$16)*(1-$B$16/$B$17)/($B$14-$B$16)/(1+$B$14)^4.5-$B$18+$B$19)/$B$20 -> 326.49375 | G32: =(SUMPRODUCT($C$8:$G$8,1/(1+$B$14)^$C$13:$G$13,$B$5*(1+$B32)^$C$7:$G$7*((G$24-$C$9:$G$9)*(1-$B$4)+$C$9:$G$9-$C$10:$G$10-$C$11:$G$11)+$B$5*(1+$B32)^($C$7:$G$7-1)*$C$12:$G$12)+$B$5*(1+$B32)^5*(G$24-$G$9)*(1-$B$4)*(1+$B$16)*(1-$B$16/$B$17)/($B$14-$B$16)/(1+$B$14)^4.5-$B$18+$B$19)/$B$20 -> 421.93773 | H32: =(SUMPRODUCT($C$8:$G$8,1/(1+$B$14)^$C$13:$G$13,$B$5*(1+$B32)^$C$7:$G$7*((H$24-$C$9:$G$9)*(1-$B$4)+$C$9:$G$9-$C$10:$G$10-$C$11:$G$11)+$B$5*(1+$B32)^($C$7:$G$7-1)*$C$12:$G$12)+$B$5*(1+$B32)^5*(H$24-$G$9)*(1-$B$4)*(1+$B$16)*(1-$B$16/$B$17)/($B$14-$B$16)/(1+$B$14)^4.5-$B$18+$B$19)/$B$20 -> 517.38171
B33: 0.22 | C33: =(SUMPRODUCT($C$8:$G$8,1/(1+$B$14)^$C$13:$G$13,$B$5*(1+$B33)^$C$7:$G$7*((C$24-$C$9:$G$9)*(1-$B$4)+$C$9:$G$9-$C$10:$G$10-$C$11:$G$11)+$B$5*(1+$B33)^($C$7:$G$7-1)*$C$12:$G$12)+$B$5*(1+$B33)^5*(C$24-$G$9)*(1-$B$4)*(1+$B$16)*(1-$B$16/$B$17)/($B$14-$B$16)/(1+$B$14)^4.5-$B$18+$B$19)/$B$20 -> 53.330962 | D33: =(SUMPRODUCT($C$8:$G$8,1/(1+$B$14)^$C$13:$G$13,$B$5*(1+$B33)^$C$7:$G$7*((D$24-$C$9:$G$9)*(1-$B$4)+$C$9:$G$9-$C$10:$G$10-$C$11:$G$11)+$B$5*(1+$B33)^($C$7:$G$7-1)*$C$12:$G$12)+$B$5*(1+$B33)^5*(D$24-$G$9)*(1-$B$4)*(1+$B$16)*(1-$B$16/$B$17)/($B$14-$B$16)/(1+$B$14)^4.5-$B$18+$B$19)/$B$20 -> 156.10515 | E33: =(SUMPRODUCT($C$8:$G$8,1/(1+$B$14)^$C$13:$G$13,$B$5*(1+$B33)^$C$7:$G$7*((E$24-$C$9:$G$9)*(1-$B$4)+$C$9:$G$9-$C$10:$G$10-$C$11:$G$11)+$B$5*(1+$B33)^($C$7:$G$7-1)*$C$12:$G$12)+$B$5*(1+$B33)^5*(E$24-$G$9)*(1-$B$4)*(1+$B$16)*(1-$B$16/$B$17)/($B$14-$B$16)/(1+$B$14)^4.5-$B$18+$B$19)/$B$20 -> 258.87933 | F33: =(SUMPRODUCT($C$8:$G$8,1/(1+$B$14)^$C$13:$G$13,$B$5*(1+$B33)^$C$7:$G$7*((F$24-$C$9:$G$9)*(1-$B$4)+$C$9:$G$9-$C$10:$G$10-$C$11:$G$11)+$B$5*(1+$B33)^($C$7:$G$7-1)*$C$12:$G$12)+$B$5*(1+$B33)^5*(F$24-$G$9)*(1-$B$4)*(1+$B$16)*(1-$B$16/$B$17)/($B$14-$B$16)/(1+$B$14)^4.5-$B$18+$B$19)/$B$20 -> 361.65352 | G33: =(SUMPRODUCT($C$8:$G$8,1/(1+$B$14)^$C$13:$G$13,$B$5*(1+$B33)^$C$7:$G$7*((G$24-$C$9:$G$9)*(1-$B$4)+$C$9:$G$9-$C$10:$G$10-$C$11:$G$11)+$B$5*(1+$B33)^($C$7:$G$7-1)*$C$12:$G$12)+$B$5*(1+$B33)^5*(G$24-$G$9)*(1-$B$4)*(1+$B$16)*(1-$B$16/$B$17)/($B$14-$B$16)/(1+$B$14)^4.5-$B$18+$B$19)/$B$20 -> 464.4277 | H33: =(SUMPRODUCT($C$8:$G$8,1/(1+$B$14)^$C$13:$G$13,$B$5*(1+$B33)^$C$7:$G$7*((H$24-$C$9:$G$9)*(1-$B$4)+$C$9:$G$9-$C$10:$G$10-$C$11:$G$11)+$B$5*(1+$B33)^($C$7:$G$7-1)*$C$12:$G$12)+$B$5*(1+$B33)^5*(H$24-$G$9)*(1-$B$4)*(1+$B$16)*(1-$B$16/$B$17)/($B$14-$B$16)/(1+$B$14)^4.5-$B$18+$B$19)/$B$20 -> 567.20188
A35: GRID B: at the lower WACC in B15
B36: CAGR \ margin | C36: 0.16 | D36: 0.18 | E36: 0.2 | F36: 0.22 | G36: 0.24 | H36: 0.26
B37: 0.06 | C37: =(SUMPRODUCT($C$8:$G$8,1/(1+$B$15)^$C$13:$G$13,$B$5*(1+$B37)^$C$7:$G$7*((C$36-$C$9:$G$9)*(1-$B$4)+$C$9:$G$9-$C$10:$G$10-$C$11:$G$11)+$B$5*(1+$B37)^($C$7:$G$7-1)*$C$12:$G$12)+$B$5*(1+$B37)^5*(C$36-$G$9)*(1-$B$4)*(1+$B$16)*(1-$B$16/$B$17)/($B$15-$B$16)/(1+$B$15)^4.5-$B$18+$B$19)/$B$20 -> 53.949488 | D37: =(SUMPRODUCT($C$8:$G$8,1/(1+$B$15)^$C$13:$G$13,$B$5*(1+$B37)^$C$7:$G$7*((D$36-$C$9:$G$9)*(1-$B$4)+$C$9:$G$9-$C$10:$G$10-$C$11:$G$11)+$B$5*(1+$B37)^($C$7:$G$7-1)*$C$12:$G$12)+$B$5*(1+$B37)^5*(D$36-$G$9)*(1-$B$4)*(1+$B$16)*(1-$B$16/$B$17)/($B$15-$B$16)/(1+$B$15)^4.5-$B$18+$B$19)/$B$20 -> 127.72123 | E37: =(SUMPRODUCT($C$8:$G$8,1/(1+$B$15)^$C$13:$G$13,$B$5*(1+$B37)^$C$7:$G$7*((E$36-$C$9:$G$9)*(1-$B$4)+$C$9:$G$9-$C$10:$G$10-$C$11:$G$11)+$B$5*(1+$B37)^($C$7:$G$7-1)*$C$12:$G$12)+$B$5*(1+$B37)^5*(E$36-$G$9)*(1-$B$4)*(1+$B$16)*(1-$B$16/$B$17)/($B$15-$B$16)/(1+$B$15)^4.5-$B$18+$B$19)/$B$20 -> 201.49297 | F37: =(SUMPRODUCT($C$8:$G$8,1/(1+$B$15)^$C$13:$G$13,$B$5*(1+$B37)^$C$7:$G$7*((F$36-$C$9:$G$9)*(1-$B$4)+$C$9:$G$9-$C$10:$G$10-$C$11:$G$11)+$B$5*(1+$B37)^($C$7:$G$7-1)*$C$12:$G$12)+$B$5*(1+$B37)^5*(F$36-$G$9)*(1-$B$4)*(1+$B$16)*(1-$B$16/$B$17)/($B$15-$B$16)/(1+$B$15)^4.5-$B$18+$B$19)/$B$20 -> 275.26471 | G37: =(SUMPRODUCT($C$8:$G$8,1/(1+$B$15)^$C$13:$G$13,$B$5*(1+$B37)^$C$7:$G$7*((G$36-$C$9:$G$9)*(1-$B$4)+$C$9:$G$9-$C$10:$G$10-$C$11:$G$11)+$B$5*(1+$B37)^($C$7:$G$7-1)*$C$12:$G$12)+$B$5*(1+$B37)^5*(G$36-$G$9)*(1-$B$4)*(1+$B$16)*(1-$B$16/$B$17)/($B$15-$B$16)/(1+$B$15)^4.5-$B$18+$B$19)/$B$20 -> 349.03645 | H37: =(SUMPRODUCT($C$8:$G$8,1/(1+$B$15)^$C$13:$G$13,$B$5*(1+$B37)^$C$7:$G$7*((H$36-$C$9:$G$9)*(1-$B$4)+$C$9:$G$9-$C$10:$G$10-$C$11:$G$11)+$B$5*(1+$B37)^($C$7:$G$7-1)*$C$12:$G$12)+$B$5*(1+$B37)^5*(H$36-$G$9)*(1-$B$4)*(1+$B$16)*(1-$B$16/$B$17)/($B$15-$B$16)/(1+$B$15)^4.5-$B$18+$B$19)/$B$20 -> 422.80819
B38: 0.08 | C38: =(SUMPRODUCT($C$8:$G$8,1/(1+$B$15)^$C$13:$G$13,$B$5*(1+$B38)^$C$7:$G$7*((C$36-$C$9:$G$9)*(1-$B$4)+$C$9:$G$9-$C$10:$G$10-$C$11:$G$11)+$B$5*(1+$B38)^($C$7:$G$7-1)*$C$12:$G$12)+$B$5*(1+$B38)^5*(C$36-$G$9)*(1-$B$4)*(1+$B$16)*(1-$B$16/$B$17)/($B$15-$B$16)/(1+$B$15)^4.5-$B$18+$B$19)/$B$20 -> 70.548748 | D38: =(SUMPRODUCT($C$8:$G$8,1/(1+$B$15)^$C$13:$G$13,$B$5*(1+$B38)^$C$7:$G$7*((D$36-$C$9:$G$9)*(1-$B$4)+$C$9:$G$9-$C$10:$G$10-$C$11:$G$11)+$B$5*(1+$B38)^($C$7:$G$7-1)*$C$12:$G$12)+$B$5*(1+$B38)^5*(D$36-$G$9)*(1-$B$4)*(1+$B$16)*(1-$B$16/$B$17)/($B$15-$B$16)/(1+$B$15)^4.5-$B$18+$B$19)/$B$20 -> 150.76192 | E38: =(SUMPRODUCT($C$8:$G$8,1/(1+$B$15)^$C$13:$G$13,$B$5*(1+$B38)^$C$7:$G$7*((E$36-$C$9:$G$9)*(1-$B$4)+$C$9:$G$9-$C$10:$G$10-$C$11:$G$11)+$B$5*(1+$B38)^($C$7:$G$7-1)*$C$12:$G$12)+$B$5*(1+$B38)^5*(E$36-$G$9)*(1-$B$4)*(1+$B$16)*(1-$B$16/$B$17)/($B$15-$B$16)/(1+$B$15)^4.5-$B$18+$B$19)/$B$20 -> 230.97509 | F38: =(SUMPRODUCT($C$8:$G$8,1/(1+$B$15)^$C$13:$G$13,$B$5*(1+$B38)^$C$7:$G$7*((F$36-$C$9:$G$9)*(1-$B$4)+$C$9:$G$9-$C$10:$G$10-$C$11:$G$11)+$B$5*(1+$B38)^($C$7:$G$7-1)*$C$12:$G$12)+$B$5*(1+$B38)^5*(F$36-$G$9)*(1-$B$4)*(1+$B$16)*(1-$B$16/$B$17)/($B$15-$B$16)/(1+$B$15)^4.5-$B$18+$B$19)/$B$20 -> 311.18826 | G38: =(SUMPRODUCT($C$8:$G$8,1/(1+$B$15)^$C$13:$G$13,$B$5*(1+$B38)^$C$7:$G$7*((G$36-$C$9:$G$9)*(1-$B$4)+$C$9:$G$9-$C$10:$G$10-$C$11:$G$11)+$B$5*(1+$B38)^($C$7:$G$7-1)*$C$12:$G$12)+$B$5*(1+$B38)^5*(G$36-$G$9)*(1-$B$4)*(1+$B$16)*(1-$B$16/$B$17)/($B$15-$B$16)/(1+$B$15)^4.5-$B$18+$B$19)/$B$20 -> 391.40144 | H38: =(SUMPRODUCT($C$8:$G$8,1/(1+$B$15)^$C$13:$G$13,$B$5*(1+$B38)^$C$7:$G$7*((H$36-$C$9:$G$9)*(1-$B$4)+$C$9:$G$9-$C$10:$G$10-$C$11:$G$11)+$B$5*(1+$B38)^($C$7:$G$7-1)*$C$12:$G$12)+$B$5*(1+$B38)^5*(H$36-$G$9)*(1-$B$4)*(1+$B$16)*(1-$B$16/$B$17)/($B$15-$B$16)/(1+$B$15)^4.5-$B$18+$B$19)/$B$20 -> 471.61461
B39: 0.1 | C39: =(SUMPRODUCT($C$8:$G$8,1/(1+$B$15)^$C$13:$G$13,$B$5*(1+$B39)^$C$7:$G$7*((C$36-$C$9:$G$9)*(1-$B$4)+$C$9:$G$9-$C$10:$G$10-$C$11:$G$11)+$B$5*(1+$B39)^($C$7:$G$7-1)*$C$12:$G$12)+$B$5*(1+$B39)^5*(C$36-$G$9)*(1-$B$4)*(1+$B$16)*(1-$B$16/$B$17)/($B$15-$B$16)/(1+$B$15)^4.5-$B$18+$B$19)/$B$20 -> 88.30445 | D39: =(SUMPRODUCT($C$8:$G$8,1/(1+$B$15)^$C$13:$G$13,$B$5*(1+$B39)^$C$7:$G$7*((D$36-$C$9:$G$9)*(1-$B$4)+$C$9:$G$9-$C$10:$G$10-$C$11:$G$11)+$B$5*(1+$B39)^($C$7:$G$7-1)*$C$12:$G$12)+$B$5*(1+$B39)^5*(D$36-$G$9)*(1-$B$4)*(1+$B$16)*(1-$B$16/$B$17)/($B$15-$B$16)/(1+$B$15)^4.5-$B$18+$B$19)/$B$20 -> 175.42174 | E39: =(SUMPRODUCT($C$8:$G$8,1/(1+$B$15)^$C$13:$G$13,$B$5*(1+$B39)^$C$7:$G$7*((E$36-$C$9:$G$9)*(1-$B$4)+$C$9:$G$9-$C$10:$G$10-$C$11:$G$11)+$B$5*(1+$B39)^($C$7:$G$7-1)*$C$12:$G$12)+$B$5*(1+$B39)^5*(E$36-$G$9)*(1-$B$4)*(1+$B$16)*(1-$B$16/$B$17)/($B$15-$B$16)/(1+$B$15)^4.5-$B$18+$B$19)/$B$20 -> 262.53903 | F39: =(SUMPRODUCT($C$8:$G$8,1/(1+$B$15)^$C$13:$G$13,$B$5*(1+$B39)^$C$7:$G$7*((F$36-$C$9:$G$9)*(1-$B$4)+$C$9:$G$9-$C$10:$G$10-$C$11:$G$11)+$B$5*(1+$B39)^($C$7:$G$7-1)*$C$12:$G$12)+$B$5*(1+$B39)^5*(F$36-$G$9)*(1-$B$4)*(1+$B$16)*(1-$B$16/$B$17)/($B$15-$B$16)/(1+$B$15)^4.5-$B$18+$B$19)/$B$20 -> 349.65633 | G39: =(SUMPRODUCT($C$8:$G$8,1/(1+$B$15)^$C$13:$G$13,$B$5*(1+$B39)^$C$7:$G$7*((G$36-$C$9:$G$9)*(1-$B$4)+$C$9:$G$9-$C$10:$G$10-$C$11:$G$11)+$B$5*(1+$B39)^($C$7:$G$7-1)*$C$12:$G$12)+$B$5*(1+$B39)^5*(G$36-$G$9)*(1-$B$4)*(1+$B$16)*(1-$B$16/$B$17)/($B$15-$B$16)/(1+$B$15)^4.5-$B$18+$B$19)/$B$20 -> 436.77362 | H39: =(SUMPRODUCT($C$8:$G$8,1/(1+$B$15)^$C$13:$G$13,$B$5*(1+$B39)^$C$7:$G$7*((H$36-$C$9:$G$9)*(1-$B$4)+$C$9:$G$9-$C$10:$G$10-$C$11:$G$11)+$B$5*(1+$B39)^($C$7:$G$7-1)*$C$12:$G$12)+$B$5*(1+$B39)^5*(H$36-$G$9)*(1-$B$4)*(1+$B$16)*(1-$B$16/$B$17)/($B$15-$B$16)/(1+$B$15)^4.5-$B$18+$B$19)/$B$20 -> 523.89091
B40: 0.12 | C40: =(SUMPRODUCT($C$8:$G$8,1/(1+$B$15)^$C$13:$G$13,$B$5*(1+$B40)^$C$7:$G$7*((C$36-$C$9:$G$9)*(1-$B$4)+$C$9:$G$9-$C$10:$G$10-$C$11:$G$11)+$B$5*(1+$B40)^($C$7:$G$7-1)*$C$12:$G$12)+$B$5*(1+$B40)^5*(C$36-$G$9)*(1-$B$4)*(1+$B$16)*(1-$B$16/$B$17)/($B$15-$B$16)/(1+$B$15)^4.5-$B$18+$B$19)/$B$20 -> 107.28146 | D40: =(SUMPRODUCT($C$8:$G$8,1/(1+$B$15)^$C$13:$G$13,$B$5*(1+$B40)^$C$7:$G$7*((D$36-$C$9:$G$9)*(1-$B$4)+$C$9:$G$9-$C$10:$G$10-$C$11:$G$11)+$B$5*(1+$B40)^($C$7:$G$7-1)*$C$12:$G$12)+$B$5*(1+$B40)^5*(D$36-$G$9)*(1-$B$4)*(1+$B$16)*(1-$B$16/$B$17)/($B$15-$B$16)/(1+$B$15)^4.5-$B$18+$B$19)/$B$20 -> 201.79076 | E40: =(SUMPRODUCT($C$8:$G$8,1/(1+$B$15)^$C$13:$G$13,$B$5*(1+$B40)^$C$7:$G$7*((E$36-$C$9:$G$9)*(1-$B$4)+$C$9:$G$9-$C$10:$G$10-$C$11:$G$11)+$B$5*(1+$B40)^($C$7:$G$7-1)*$C$12:$G$12)+$B$5*(1+$B40)^5*(E$36-$G$9)*(1-$B$4)*(1+$B$16)*(1-$B$16/$B$17)/($B$15-$B$16)/(1+$B$15)^4.5-$B$18+$B$19)/$B$20 -> 296.30006 | F40: =(SUMPRODUCT($C$8:$G$8,1/(1+$B$15)^$C$13:$G$13,$B$5*(1+$B40)^$C$7:$G$7*((F$36-$C$9:$G$9)*(1-$B$4)+$C$9:$G$9-$C$10:$G$10-$C$11:$G$11)+$B$5*(1+$B40)^($C$7:$G$7-1)*$C$12:$G$12)+$B$5*(1+$B40)^5*(F$36-$G$9)*(1-$B$4)*(1+$B$16)*(1-$B$16/$B$17)/($B$15-$B$16)/(1+$B$15)^4.5-$B$18+$B$19)/$B$20 -> 390.80935 | G40: =(SUMPRODUCT($C$8:$G$8,1/(1+$B$15)^$C$13:$G$13,$B$5*(1+$B40)^$C$7:$G$7*((G$36-$C$9:$G$9)*(1-$B$4)+$C$9:$G$9-$C$10:$G$10-$C$11:$G$11)+$B$5*(1+$B40)^($C$7:$G$7-1)*$C$12:$G$12)+$B$5*(1+$B40)^5*(G$36-$G$9)*(1-$B$4)*(1+$B$16)*(1-$B$16/$B$17)/($B$15-$B$16)/(1+$B$15)^4.5-$B$18+$B$19)/$B$20 -> 485.31865 | H40: =(SUMPRODUCT($C$8:$G$8,1/(1+$B$15)^$C$13:$G$13,$B$5*(1+$B40)^$C$7:$G$7*((H$36-$C$9:$G$9)*(1-$B$4)+$C$9:$G$9-$C$10:$G$10-$C$11:$G$11)+$B$5*(1+$B40)^($C$7:$G$7-1)*$C$12:$G$12)+$B$5*(1+$B40)^5*(H$36-$G$9)*(1-$B$4)*(1+$B$16)*(1-$B$16/$B$17)/($B$15-$B$16)/(1+$B$15)^4.5-$B$18+$B$19)/$B$20 -> 579.82795
B41: 0.14 | C41: =(SUMPRODUCT($C$8:$G$8,1/(1+$B$15)^$C$13:$G$13,$B$5*(1+$B41)^$C$7:$G$7*((C$36-$C$9:$G$9)*(1-$B$4)+$C$9:$G$9-$C$10:$G$10-$C$11:$G$11)+$B$5*(1+$B41)^($C$7:$G$7-1)*$C$12:$G$12)+$B$5*(1+$B41)^5*(C$36-$G$9)*(1-$B$4)*(1+$B$16)*(1-$B$16/$B$17)/($B$15-$B$16)/(1+$B$15)^4.5-$B$18+$B$19)/$B$20 -> 127.54704 | D41: =(SUMPRODUCT($C$8:$G$8,1/(1+$B$15)^$C$13:$G$13,$B$5*(1+$B41)^$C$7:$G$7*((D$36-$C$9:$G$9)*(1-$B$4)+$C$9:$G$9-$C$10:$G$10-$C$11:$G$11)+$B$5*(1+$B41)^($C$7:$G$7-1)*$C$12:$G$12)+$B$5*(1+$B41)^5*(D$36-$G$9)*(1-$B$4)*(1+$B$16)*(1-$B$16/$B$17)/($B$15-$B$16)/(1+$B$15)^4.5-$B$18+$B$19)/$B$20 -> 229.96234 | E41: =(SUMPRODUCT($C$8:$G$8,1/(1+$B$15)^$C$13:$G$13,$B$5*(1+$B41)^$C$7:$G$7*((E$36-$C$9:$G$9)*(1-$B$4)+$C$9:$G$9-$C$10:$G$10-$C$11:$G$11)+$B$5*(1+$B41)^($C$7:$G$7-1)*$C$12:$G$12)+$B$5*(1+$B41)^5*(E$36-$G$9)*(1-$B$4)*(1+$B$16)*(1-$B$16/$B$17)/($B$15-$B$16)/(1+$B$15)^4.5-$B$18+$B$19)/$B$20 -> 332.37763 | F41: =(SUMPRODUCT($C$8:$G$8,1/(1+$B$15)^$C$13:$G$13,$B$5*(1+$B41)^$C$7:$G$7*((F$36-$C$9:$G$9)*(1-$B$4)+$C$9:$G$9-$C$10:$G$10-$C$11:$G$11)+$B$5*(1+$B41)^($C$7:$G$7-1)*$C$12:$G$12)+$B$5*(1+$B41)^5*(F$36-$G$9)*(1-$B$4)*(1+$B$16)*(1-$B$16/$B$17)/($B$15-$B$16)/(1+$B$15)^4.5-$B$18+$B$19)/$B$20 -> 434.79293 | G41: =(SUMPRODUCT($C$8:$G$8,1/(1+$B$15)^$C$13:$G$13,$B$5*(1+$B41)^$C$7:$G$7*((G$36-$C$9:$G$9)*(1-$B$4)+$C$9:$G$9-$C$10:$G$10-$C$11:$G$11)+$B$5*(1+$B41)^($C$7:$G$7-1)*$C$12:$G$12)+$B$5*(1+$B41)^5*(G$36-$G$9)*(1-$B$4)*(1+$B$16)*(1-$B$16/$B$17)/($B$15-$B$16)/(1+$B$15)^4.5-$B$18+$B$19)/$B$20 -> 537.20822 | H41: =(SUMPRODUCT($C$8:$G$8,1/(1+$B$15)^$C$13:$G$13,$B$5*(1+$B41)^$C$7:$G$7*((H$36-$C$9:$G$9)*(1-$B$4)+$C$9:$G$9-$C$10:$G$10-$C$11:$G$11)+$B$5*(1+$B41)^($C$7:$G$7-1)*$C$12:$G$12)+$B$5*(1+$B41)^5*(H$36-$G$9)*(1-$B$4)*(1+$B$16)*(1-$B$16/$B$17)/($B$15-$B$16)/(1+$B$15)^4.5-$B$18+$B$19)/$B$20 -> 639.62352
B42: 0.16 | C42: =(SUMPRODUCT($C$8:$G$8,1/(1+$B$15)^$C$13:$G$13,$B$5*(1+$B42)^$C$7:$G$7*((C$36-$C$9:$G$9)*(1-$B$4)+$C$9:$G$9-$C$10:$G$10-$C$11:$G$11)+$B$5*(1+$B42)^($C$7:$G$7-1)*$C$12:$G$12)+$B$5*(1+$B42)^5*(C$36-$G$9)*(1-$B$4)*(1+$B$16)*(1-$B$16/$B$17)/($B$15-$B$16)/(1+$B$15)^4.5-$B$18+$B$19)/$B$20 -> 149.17087 | D42: =(SUMPRODUCT($C$8:$G$8,1/(1+$B$15)^$C$13:$G$13,$B$5*(1+$B42)^$C$7:$G$7*((D$36-$C$9:$G$9)*(1-$B$4)+$C$9:$G$9-$C$10:$G$10-$C$11:$G$11)+$B$5*(1+$B42)^($C$7:$G$7-1)*$C$12:$G$12)+$B$5*(1+$B42)^5*(D$36-$G$9)*(1-$B$4)*(1+$B$16)*(1-$B$16/$B$17)/($B$15-$B$16)/(1+$B$15)^4.5-$B$18+$B$19)/$B$20 -> 260.03319 | E42: =(SUMPRODUCT($C$8:$G$8,1/(1+$B$15)^$C$13:$G$13,$B$5*(1+$B42)^$C$7:$G$7*((E$36-$C$9:$G$9)*(1-$B$4)+$C$9:$G$9-$C$10:$G$10-$C$11:$G$11)+$B$5*(1+$B42)^($C$7:$G$7-1)*$C$12:$G$12)+$B$5*(1+$B42)^5*(E$36-$G$9)*(1-$B$4)*(1+$B$16)*(1-$B$16/$B$17)/($B$15-$B$16)/(1+$B$15)^4.5-$B$18+$B$19)/$B$20 -> 370.89552 | F42: =(SUMPRODUCT($C$8:$G$8,1/(1+$B$15)^$C$13:$G$13,$B$5*(1+$B42)^$C$7:$G$7*((F$36-$C$9:$G$9)*(1-$B$4)+$C$9:$G$9-$C$10:$G$10-$C$11:$G$11)+$B$5*(1+$B42)^($C$7:$G$7-1)*$C$12:$G$12)+$B$5*(1+$B42)^5*(F$36-$G$9)*(1-$B$4)*(1+$B$16)*(1-$B$16/$B$17)/($B$15-$B$16)/(1+$B$15)^4.5-$B$18+$B$19)/$B$20 -> 481.75784 | G42: =(SUMPRODUCT($C$8:$G$8,1/(1+$B$15)^$C$13:$G$13,$B$5*(1+$B42)^$C$7:$G$7*((G$36-$C$9:$G$9)*(1-$B$4)+$C$9:$G$9-$C$10:$G$10-$C$11:$G$11)+$B$5*(1+$B42)^($C$7:$G$7-1)*$C$12:$G$12)+$B$5*(1+$B42)^5*(G$36-$G$9)*(1-$B$4)*(1+$B$16)*(1-$B$16/$B$17)/($B$15-$B$16)/(1+$B$15)^4.5-$B$18+$B$19)/$B$20 -> 592.62016 | H42: =(SUMPRODUCT($C$8:$G$8,1/(1+$B$15)^$C$13:$G$13,$B$5*(1+$B42)^$C$7:$G$7*((H$36-$C$9:$G$9)*(1-$B$4)+$C$9:$G$9-$C$10:$G$10-$C$11:$G$11)+$B$5*(1+$B42)^($C$7:$G$7-1)*$C$12:$G$12)+$B$5*(1+$B42)^5*(H$36-$G$9)*(1-$B$4)*(1+$B$16)*(1-$B$16/$B$17)/($B$15-$B$16)/(1+$B$15)^4.5-$B$18+$B$19)/$B$20 -> 703.48248
B43: 0.18 | C43: =(SUMPRODUCT($C$8:$G$8,1/(1+$B$15)^$C$13:$G$13,$B$5*(1+$B43)^$C$7:$G$7*((C$36-$C$9:$G$9)*(1-$B$4)+$C$9:$G$9-$C$10:$G$10-$C$11:$G$11)+$B$5*(1+$B43)^($C$7:$G$7-1)*$C$12:$G$12)+$B$5*(1+$B43)^5*(C$36-$G$9)*(1-$B$4)*(1+$B$16)*(1-$B$16/$B$17)/($B$15-$B$16)/(1+$B$15)^4.5-$B$18+$B$19)/$B$20 -> 172.22512 | D43: =(SUMPRODUCT($C$8:$G$8,1/(1+$B$15)^$C$13:$G$13,$B$5*(1+$B43)^$C$7:$G$7*((D$36-$C$9:$G$9)*(1-$B$4)+$C$9:$G$9-$C$10:$G$10-$C$11:$G$11)+$B$5*(1+$B43)^($C$7:$G$7-1)*$C$12:$G$12)+$B$5*(1+$B43)^5*(D$36-$G$9)*(1-$B$4)*(1+$B$16)*(1-$B$16/$B$17)/($B$15-$B$16)/(1+$B$15)^4.5-$B$18+$B$19)/$B$20 -> 292.10347 | E43: =(SUMPRODUCT($C$8:$G$8,1/(1+$B$15)^$C$13:$G$13,$B$5*(1+$B43)^$C$7:$G$7*((E$36-$C$9:$G$9)*(1-$B$4)+$C$9:$G$9-$C$10:$G$10-$C$11:$G$11)+$B$5*(1+$B43)^($C$7:$G$7-1)*$C$12:$G$12)+$B$5*(1+$B43)^5*(E$36-$G$9)*(1-$B$4)*(1+$B$16)*(1-$B$16/$B$17)/($B$15-$B$16)/(1+$B$15)^4.5-$B$18+$B$19)/$B$20 -> 411.98183 | F43: =(SUMPRODUCT($C$8:$G$8,1/(1+$B$15)^$C$13:$G$13,$B$5*(1+$B43)^$C$7:$G$7*((F$36-$C$9:$G$9)*(1-$B$4)+$C$9:$G$9-$C$10:$G$10-$C$11:$G$11)+$B$5*(1+$B43)^($C$7:$G$7-1)*$C$12:$G$12)+$B$5*(1+$B43)^5*(F$36-$G$9)*(1-$B$4)*(1+$B$16)*(1-$B$16/$B$17)/($B$15-$B$16)/(1+$B$15)^4.5-$B$18+$B$19)/$B$20 -> 531.86019 | G43: =(SUMPRODUCT($C$8:$G$8,1/(1+$B$15)^$C$13:$G$13,$B$5*(1+$B43)^$C$7:$G$7*((G$36-$C$9:$G$9)*(1-$B$4)+$C$9:$G$9-$C$10:$G$10-$C$11:$G$11)+$B$5*(1+$B43)^($C$7:$G$7-1)*$C$12:$G$12)+$B$5*(1+$B43)^5*(G$36-$G$9)*(1-$B$4)*(1+$B$16)*(1-$B$16/$B$17)/($B$15-$B$16)/(1+$B$15)^4.5-$B$18+$B$19)/$B$20 -> 651.73855 | H43: =(SUMPRODUCT($C$8:$G$8,1/(1+$B$15)^$C$13:$G$13,$B$5*(1+$B43)^$C$7:$G$7*((H$36-$C$9:$G$9)*(1-$B$4)+$C$9:$G$9-$C$10:$G$10-$C$11:$G$11)+$B$5*(1+$B43)^($C$7:$G$7-1)*$C$12:$G$12)+$B$5*(1+$B43)^5*(H$36-$G$9)*(1-$B$4)*(1+$B$16)*(1-$B$16/$B$17)/($B$15-$B$16)/(1+$B$15)^4.5-$B$18+$B$19)/$B$20 -> 771.6169
...
